<?xml version='1.0'?>


<robot name="hosp_bot" xmlns:xacro="http://www.ros.org/wiki/xacro">

  <!-- import URDF files -->

  <xacro:include filename="$(find hosp_bot)/urdf/common_properties.xacro"/>
  <xacro:include filename="$(find hosp_bot)/urdf/hosp_bot.gazebo" />

  <!-- robot_footprint -->

  <link name="robot_footprint"></link>

  <joint name="robot_footprint_joint" type="fixed">
    <origin xyz="0 0 0" rpy="0 0 0" />
    <parent link="robot_footprint"/>
    <child link="chassis" />
  </joint>

  <!-- chassis -->

  <link name='chassis'>
    <pose>0 0 0.1 0 0 0</pose>

    <visual name='chassis_visual'>
      <origin xyz="0 0 0.05" rpy=" 0 0 0"/>
      <geometry>
        <box size=".4 .2 .15"/>
      </geometry>
      <material name="white"/>
    </visual>

    <inertial>
      <mass value="10.0"/>
      <origin xyz="0.0 0 0" rpy=" 0 0 0"/>
      <inertia
          ixx="0.1" ixy="0" ixz="0"
          iyy="0.1" iyz="0"
          izz="0.1"
      />
    </inertial>

    <collision name='chassis_collision'>
      <origin xyz="0 0 0.05" rpy=" 0 0 0"/> 
      <geometry>
        <box size=".4 .2 .15"/>
      </geometry>
    </collision>

  </link>
     
  <!-- front_left_wheel -->
  

  <joint type="continuous" name="front_left_wheel_joint">
      <origin xyz="0.15 0.15 0" rpy="0 0 0"/>
      <child link="front_left_wheel"/>
      <parent link="chassis"/>
      <axis xyz="0 1 0" rpy="0 0 0"/>
      <limit effort="30" velocity="0.1"/>
      <joint_properties damping="0" friction="0"/>
  </joint>

  <link name="front_left_wheel">

    <visual name='front_left_wheel_visual'>
      <origin xyz="0 0 0" rpy=" 0 1.5707 1.5707"/>
      <geometry>
        <cylinder radius="0.1" length="0.05"/>
      </geometry>
      <material name="black"/>
    </visual>

   <collision name='front_left_wheel_collision'>
      <origin xyz="0 0 0" rpy=" 0 1.5707 1.5707"/>
      <geometry>
        <cylinder radius="0.1" length="0.05"/>
      </geometry>
   </collision>

    <inertial>
      <mass value="3.0"/>
      <origin xyz="0.0 0 0" rpy=" 0 1.5707 1.5707"/>
      <inertia
          ixx="0.1" ixy="0" ixz="0"
          iyy="0.1" iyz="0"
          izz="0.1"
      />
    </inertial>

  </link>

  
  <!-- front_right_wheel -->
  

  <joint type="continuous" name="front_right_wheel_joint">
      <origin xyz="0.15 -0.15 0" rpy="0 0 0"/>
      <child link="front_right_wheel"/>
      <parent link="chassis"/>
      <axis xyz="0 1 0" rpy="0 0 0"/>
      <limit effort="30" velocity="0.1"/>
      <joint_properties damping="0" friction="0"/>
  </joint>
  

  <link name="front_right_wheel">

    <visual name='front_right_wheel_visual'>
      <origin xyz="0 0 0" rpy=" 0 1.5707 1.5707"/>
      <geometry>
        <cylinder radius="0.1" length="0.05"/>
      </geometry>
      <material name="black"/>
    </visual>

    <collision name='front_right_wheel_collision'>
      <origin xyz="0 0 0" rpy=" 0 1.5707 1.5707"/>
      <geometry>
        <cylinder radius="0.1" length="0.05"/>
      </geometry>
    </collision>

    <inertial>
      <mass value="3.0"/>
      <origin xyz="0.0 0 0" rpy=" 0 1.5707 1.5707"/>
      <inertia
          ixx="0.1" ixy="0" ixz="0"
          iyy="0.1" iyz="0"
          izz="0.1"
      />
    </inertial>

  </link>

  <!-- back_left_wheel -->
  
  <joint type="continuous" name="back_left_wheel_joint">
      <origin xyz="-0.15 0.15 0" rpy="0 0 0"/>
      <child link="back_left_wheel"/>
      <parent link="chassis"/>
      <axis xyz="0 1 0" rpy="0 0 0"/>
      <limit effort="30" velocity="0.1"/>
      <joint_properties damping="0" friction="0"/>
  </joint>

  <link name="back_left_wheel">

    <visual name='back_left_wheel_visual'>
      <origin xyz="0 0 0" rpy=" 0 1.5707 1.5707"/>
      <geometry>
        <cylinder radius="0.1" length="0.05"/>
      </geometry>
      <material name="black"/>
    </visual>

   <collision name='back_left_wheel_collision'>
      <origin xyz="0 0 0" rpy=" 0 1.5707 1.5707"/>
      <geometry>
        <cylinder radius="0.1" length="0.05"/>
      </geometry>
   </collision>

    <inertial>
      <mass value="3.0"/>
      <origin xyz="0.0 0 0" rpy=" 0 1.5707 1.5707"/>
      <inertia
          ixx="0.1" ixy="0" ixz="0"
          iyy="0.1" iyz="0"
          izz="0.1"
      />
    </inertial>

  </link>


  
  <!-- back_right_wheel -->
  
 <joint type="continuous" name="back_right_wheel_joint">
      <origin xyz="-0.15 -0.15 0" rpy="0 0 0"/>
      <child link="back_right_wheel"/>
      <parent link="chassis"/>
      <axis xyz="0 1 0" rpy="0 0 0"/>
      <limit effort="30" velocity="0.1"/>
      <joint_properties damping="0" friction="0"/>
  </joint>

  <link name="back_right_wheel">

    <visual name='back_right_wheel_visual'>
      <origin xyz="0 0 0" rpy=" 0 1.5707 1.5707"/>
      <geometry>
        <cylinder radius="0.1" length="0.05"/>
      </geometry>
      <material name="black"/>
    </visual>

    <collision name='back_right_wheel_collision'>
      <origin xyz="0 0 0" rpy=" 0 1.5707 1.5707"/>
      <geometry>
        <cylinder radius="0.1" length="0.05"/>
      </geometry>
    </collision>

    <inertial>
      <mass value="3.0"/>
      <origin xyz="0.0 0 0" rpy=" 0 1.5707 1.5707"/>
      <inertia
          ixx="0.1" ixy="0" ixz="0"
          iyy="0.1" iyz="0"
          izz="0.1"
      />
    </inertial>

  </link>

 
    
  <!-- camera -->
  
  <link name="camera">

    <visual name='camera_visual'>
      <origin xyz="0 0 0.05" rpy=" 0 0 0"/>
      <geometry>
        <box size="0.05 0.05 0.05"/>
      </geometry>
      <material name="blue"/>
    </visual>

   <collision name='camera_collision'>
      <origin xyz="0 0 0" rpy=" 0 0 0"/>
      <geometry>
        <box size="0.05 0.05 0.05"/>
      </geometry>
    </collision>

    <inertial>
      <mass value="0.1"/>
      <origin xyz="0 0 0" rpy=" 0 0 0"/>
      <inertia
          ixx="1e-6" ixy="0" ixz="0"
          iyy="1e-6" iyz="0"
          izz="1e-6"
      />
    </inertial>

  </link>

  <joint type="fixed" name="camera_joint">
      <origin xyz="0.2 0 0" rpy="0 0 0"/>
      <child link="camera"/>
      <parent link="chassis"/>
      <axis xyz="1 0 0" rpy="0 0 0"/>
  </joint>
  
  <!-- hokuyo laser -->
  
  <link name="hokuyo">
    <visual>
      <origin xyz="0 0 0.0" rpy="0 0 0"/>
      <geometry>
        <mesh filename="package://hosp_bot/meshes/hokuyo.dae"/>
      </geometry>
      <material name="dark"/>
    </visual>

    <collision>
      <origin xyz="0.0 0 0" rpy="0 0 0"/>
      <geometry>
        <box size="0.1 0.1 0.1"/>
      </geometry>
    </collision>

    <inertial>
      <mass value="0.1"/>
      <origin xyz="0 0 0" rpy=" 0 0 0"/>
      <inertia
          ixx="1e-6" ixy="0" ixz="0"
          iyy="1e-6" iyz="0"
          izz="1e-6"
      />
    </inertial>
  </link>


  <joint name="scan_joint" type="fixed">
    <child link="hokuyo"/>
    <parent link="chassis"/>
    <origin xyz="0.15 0 0.15" rpy="0 0 0"/>
  </joint>

</robot>
